python3: can't open file '/home/impuls_64/agency/conf.d/bots/bot_bset69.py': [Errno 2] No such file or directory
python3: can't open file '/home/impuls_64/agency/conf.d/bots/bot_bset69.py': [Errno 2] No such file or directory
python3: can't open file '/home/impuls_64/agency/conf.d/bots/bot_bset69.py': [Errno 2] No such file or directory
python3: can't open file '/home/impuls_64/agency/conf.d/bots/bot_bset69.py': [Errno 2] No such file or directory
Unhandled exception on chat_reader
Traceback (most recent call last):
  File "/home/impuls_64/agency/.venv/lib/python3.10/site-packages/telethon/client/updates.py", line 543, in _dispatch_update
    await callback(event)
  File "/home/impuls_64/agency/bots/searcher/basic.py", line 83, in chat_reader
    valid_data = self.validator(text, event.message.sender_id)
  File "/home/impuls_64/agency/bots/searcher/basic.py", line 73, in validator
    lst_blocked_users = self.db.get_blocked_users(self.tables.blocked_users)
TypeError: SQLiteDB.get_blocked_users() takes 1 positional argument but 2 were given
